rm: human_model_output/*.parquet: No such file or directory
[2021-07-21 11:34:27] wnv                 ERROR: Used Normal distribution, lam = 0
Traceback (most recent call last):
  File "/Users/jkeithley/Documents/CIMMID/human/human_epi_models/Epi_SEIR/wnv.py", line 99, in model_func
    ddt['Ih'] = rng.poisson(lam=self.params['eta'] * self.states['Iv'])
  File "_generator.pyx", line 3093, in numpy.random._generator.Generator.poisson
  File "_common.pyx", line 865, in numpy.random._common.disc
  File "_common.pyx", line 407, in numpy.random._common.check_constraint
ValueError: lam < 0 or lam is NaN
[2021-07-21 11:34:27] wnv                 ERROR: Exception occured running model
Traceback (most recent call last):
  File "/Users/jkeithley/Documents/CIMMID/human/human_epi_models/Epi_SEIR/wnv.py", line 99, in model_func
    ddt['Ih'] = rng.poisson(lam=self.params['eta'] * self.states['Iv'])
  File "_generator.pyx", line 3093, in numpy.random._generator.Generator.poisson
  File "_common.pyx", line 865, in numpy.random._common.disc
  File "_common.pyx", line 407, in numpy.random._common.check_constraint
ValueError: lam < 0 or lam is NaN

During handling of the above exception, another exception occurred:

Traceback (most recent call last):
  File "/Users/jkeithley/Documents/CIMMID/human/human_epi_models/Epi_SEIR/vbdm.py", line 119, in run_model
    sol = solve_ivp(self.model_func, t, list(self.initial_states.values()), t_eval=t_eval)
  File "/Users/jkeithley/opt/anaconda3/envs/human-epi-env/lib/python3.8/site-packages/scipy/integrate/_ivp/ivp.py", line 576, in solve_ivp
    message = solver.step()
  File "/Users/jkeithley/opt/anaconda3/envs/human-epi-env/lib/python3.8/site-packages/scipy/integrate/_ivp/base.py", line 181, in step
    success, message = self._step_impl()
  File "/Users/jkeithley/opt/anaconda3/envs/human-epi-env/lib/python3.8/site-packages/scipy/integrate/_ivp/rk.py", line 144, in _step_impl
    y_new, f_new = rk_step(self.fun, t, y, self.f, h, self.A,
  File "/Users/jkeithley/opt/anaconda3/envs/human-epi-env/lib/python3.8/site-packages/scipy/integrate/_ivp/rk.py", line 64, in rk_step
    K[s] = fun(t + c * h, y + dy)
  File "/Users/jkeithley/opt/anaconda3/envs/human-epi-env/lib/python3.8/site-packages/scipy/integrate/_ivp/base.py", line 138, in fun
    return self.fun_single(t, y)
  File "/Users/jkeithley/opt/anaconda3/envs/human-epi-env/lib/python3.8/site-packages/scipy/integrate/_ivp/base.py", line 20, in fun_wrapped
    return np.asarray(fun(t, y), dtype=dtype)
  File "/Users/jkeithley/Documents/CIMMID/human/human_epi_models/Epi_SEIR/wnv.py", line 102, in model_func
    ddt['Ih'] = math.trunc(rng.normal(loc = self.params['eta']*self.states['Iv'], scale = math.sqrt(self.params['eta']*self.states['Iv'])))
ValueError: math domain error
Traceback (most recent call last):
  File "/Users/jkeithley/Documents/CIMMID/human/human_epi_models/Epi_SEIR/wnv.py", line 99, in model_func
    ddt['Ih'] = rng.poisson(lam=self.params['eta'] * self.states['Iv'])
  File "_generator.pyx", line 3093, in numpy.random._generator.Generator.poisson
  File "_common.pyx", line 865, in numpy.random._common.disc
  File "_common.pyx", line 407, in numpy.random._common.check_constraint
ValueError: lam < 0 or lam is NaN

During handling of the above exception, another exception occurred:

Traceback (most recent call last):
  File "models_main.py", line 40, in <module>
    main()
  File "models_main.py", line 34, in main
    disease.run_model()
  File "/Users/jkeithley/Documents/CIMMID/human/human_epi_models/Epi_SEIR/utils.py", line 100, in wrapper_timer
    value = func(self, *args, **kwargs)
  File "/Users/jkeithley/Documents/CIMMID/human/human_epi_models/Epi_SEIR/vbdm.py", line 123, in run_model
    raise e
  File "/Users/jkeithley/Documents/CIMMID/human/human_epi_models/Epi_SEIR/vbdm.py", line 119, in run_model
    sol = solve_ivp(self.model_func, t, list(self.initial_states.values()), t_eval=t_eval)
  File "/Users/jkeithley/opt/anaconda3/envs/human-epi-env/lib/python3.8/site-packages/scipy/integrate/_ivp/ivp.py", line 576, in solve_ivp
    message = solver.step()
  File "/Users/jkeithley/opt/anaconda3/envs/human-epi-env/lib/python3.8/site-packages/scipy/integrate/_ivp/base.py", line 181, in step
    success, message = self._step_impl()
  File "/Users/jkeithley/opt/anaconda3/envs/human-epi-env/lib/python3.8/site-packages/scipy/integrate/_ivp/rk.py", line 144, in _step_impl
    y_new, f_new = rk_step(self.fun, t, y, self.f, h, self.A,
  File "/Users/jkeithley/opt/anaconda3/envs/human-epi-env/lib/python3.8/site-packages/scipy/integrate/_ivp/rk.py", line 64, in rk_step
    K[s] = fun(t + c * h, y + dy)
  File "/Users/jkeithley/opt/anaconda3/envs/human-epi-env/lib/python3.8/site-packages/scipy/integrate/_ivp/base.py", line 138, in fun
    return self.fun_single(t, y)
  File "/Users/jkeithley/opt/anaconda3/envs/human-epi-env/lib/python3.8/site-packages/scipy/integrate/_ivp/base.py", line 20, in fun_wrapped
    return np.asarray(fun(t, y), dtype=dtype)
  File "/Users/jkeithley/Documents/CIMMID/human/human_epi_models/Epi_SEIR/wnv.py", line 102, in model_func
    ddt['Ih'] = math.trunc(rng.normal(loc = self.params['eta']*self.states['Iv'], scale = math.sqrt(self.params['eta']*self.states['Iv'])))
ValueError: math domain error
